/om2/user/jackking/anaconda/envs/modular_transformers/bin/python
The following values were not passed to `accelerate launch` and had defaults used instead:
	`--dynamo_backend` was set to a value of `'no'`
To avoid this warning pass in values for each of the problematic parameters or run `accelerate config`.
WARNING:torch.distributed.run:
*****************************************
Setting OMP_NUM_THREADS environment variable for each process to be 1 in default, to avoid your system being overloaded, please further tune the variable for optimal performance in your application as needed. 
*****************************************
Traceback (most recent call last):
  File "/om2/user/jackking/modular_transformers//modular_transformers/train/accelerate_train_gpt2.py", line 18, in <module>
Traceback (most recent call last):
  File "/om2/user/jackking/modular_transformers//modular_transformers/train/accelerate_train_gpt2.py", line 18, in <module>
    from modular_transformers.train.utils import Group_Texts
ModuleNotFoundError: No module named 'modular_transformers'
Traceback (most recent call last):
  File "/om2/user/jackking/modular_transformers//modular_transformers/train/accelerate_train_gpt2.py", line 18, in <module>
    from modular_transformers.train.utils import Group_Texts
ModuleNotFoundError: No module named 'modular_transformers'
    from modular_transformers.train.utils import Group_Texts
ModuleNotFoundError: No module named 'modular_transformers'
ERROR:torch.distributed.elastic.multiprocessing.api:failed (exitcode: 1) local_rank: 0 (pid: 163021) of binary: /om2/user/jackking/anaconda/envs/modular_transformers/bin/python
Traceback (most recent call last):
  File "/om2/user/jackking/anaconda/envs/modular_transformers/bin/accelerate", line 8, in <module>
    sys.exit(main())
  File "/om2/user/jackking/anaconda/envs/modular_transformers/lib/python3.8/site-packages/accelerate/commands/accelerate_cli.py", line 45, in main
    args.func(args)
  File "/om2/user/jackking/anaconda/envs/modular_transformers/lib/python3.8/site-packages/accelerate/commands/launch.py", line 900, in launch_command
    deepspeed_launcher(args)
  File "/om2/user/jackking/anaconda/envs/modular_transformers/lib/python3.8/site-packages/accelerate/commands/launch.py", line 643, in deepspeed_launcher
    distrib_run.run(args)
  File "/om2/user/jackking/anaconda/envs/modular_transformers/lib/python3.8/site-packages/torch/distributed/run.py", line 753, in run
    elastic_launch(
  File "/om2/user/jackking/anaconda/envs/modular_transformers/lib/python3.8/site-packages/torch/distributed/launcher/api.py", line 132, in __call__
    return launch_agent(self._config, self._entrypoint, list(args))
  File "/om2/user/jackking/anaconda/envs/modular_transformers/lib/python3.8/site-packages/torch/distributed/launcher/api.py", line 246, in launch_agent
    raise ChildFailedError(
torch.distributed.elastic.multiprocessing.errors.ChildFailedError: 
============================================================
/om2/user/jackking/modular_transformers//modular_transformers/train/accelerate_train_gpt2.py FAILED
------------------------------------------------------------
Failures:
[1]:
  time      : 2023-04-25_14:36:33
  host      : node094.ib.cluster
  rank      : 1 (local_rank: 1)
  exitcode  : 1 (pid: 163022)
  error_file: <N/A>
  traceback : To enable traceback see: https://pytorch.org/docs/stable/elastic/errors.html
[2]:
  time      : 2023-04-25_14:36:33
  host      : node094.ib.cluster
  rank      : 2 (local_rank: 2)
  exitcode  : 1 (pid: 163023)
  error_file: <N/A>
  traceback : To enable traceback see: https://pytorch.org/docs/stable/elastic/errors.html
------------------------------------------------------------
Root Cause (first observed failure):
[0]:
  time      : 2023-04-25_14:36:33
  host      : node094.ib.cluster
  rank      : 0 (local_rank: 0)
  exitcode  : 1 (pid: 163021)
  error_file: <N/A>
  traceback : To enable traceback see: https://pytorch.org/docs/stable/elastic/errors.html
============================================================
