/om2/user/jackking/anaconda/envs/mod_tran/bin/python
WARNING:torch.distributed.run:
*****************************************
Setting OMP_NUM_THREADS environment variable for each process to be 1 in default, to avoid your system being overloaded, please further tune the variable for optimal performance in your application as needed. 
*****************************************
Traceback (most recent call last):
  File "/om2/user/jackking/modular_transformers//modular_transformers/train/accelerate_train_gpt2.py", line 82, in <module>
    accelerator = Accelerator(log_with="wandb",gradient_accumulation_steps=gradient_accumulation_steps)
  File "/om2/user/jackking/anaconda/envs/mod_tran/lib/python3.9/site-packages/accelerate/accelerator.py", line 346, in __init__
    self.state = AcceleratorState(
  File "/om2/user/jackking/anaconda/envs/mod_tran/lib/python3.9/site-packages/accelerate/state.py", line 540, in __init__
    PartialState(cpu, **kwargs)
  File "/om2/user/jackking/anaconda/envs/mod_tran/lib/python3.9/site-packages/accelerate/state.py", line 124, in __init__
    torch.cuda.set_device(self.device)
  File "/om2/user/jackking/anaconda/envs/mod_tran/lib/python3.9/site-packages/torch/cuda/__init__.py", line 350, in set_device
    torch._C._cuda_setDevice(device)
RuntimeError: CUDA error: invalid device ordinal
CUDA kernel errors might be asynchronously reported at some other API call, so the stacktrace below might be incorrect.
For debugging consider passing CUDA_LAUNCH_BLOCKING=1.
Compile with `TORCH_USE_CUDA_DSA` to enable device-side assertions.

gpt2 size: 0.4M parameters
wandb: ERROR api_key not configured (no-tty). call wandb.login(key=[your_api_key])
Traceback (most recent call last):
  File "/om2/user/jackking/modular_transformers//modular_transformers/train/accelerate_train_gpt2.py", line 91, in <module>
    accelerator.init_trackers("bplm_gpt2", config=train_config,init_kwargs={'name':run_name})
  File "/om2/user/jackking/anaconda/envs/mod_tran/lib/python3.9/site-packages/accelerate/accelerator.py", line 548, in _inner
    return PartialState().on_main_process(function)(*args, **kwargs)
  File "/om2/user/jackking/anaconda/envs/mod_tran/lib/python3.9/site-packages/accelerate/accelerator.py", line 2034, in init_trackers
    self.trackers.append(tracker_init(project_name, **init_kwargs.get(str(tracker), {})))
  File "/om2/user/jackking/anaconda/envs/mod_tran/lib/python3.9/site-packages/accelerate/tracking.py", line 85, in execute_on_main_process
    return function(self, *args, **kwargs)
  File "/om2/user/jackking/anaconda/envs/mod_tran/lib/python3.9/site-packages/accelerate/tracking.py", line 277, in __init__
    self.run = wandb.init(project=self.run_name, **kwargs)
  File "/om2/user/jackking/anaconda/envs/mod_tran/lib/python3.9/site-packages/wandb/sdk/wandb_init.py", line 1164, in init
    raise e
  File "/om2/user/jackking/anaconda/envs/mod_tran/lib/python3.9/site-packages/wandb/sdk/wandb_init.py", line 1141, in init
    wi.setup(kwargs)
  File "/om2/user/jackking/anaconda/envs/mod_tran/lib/python3.9/site-packages/wandb/sdk/wandb_init.py", line 289, in setup
    wandb_login._login(
  File "/om2/user/jackking/anaconda/envs/mod_tran/lib/python3.9/site-packages/wandb/sdk/wandb_login.py", line 298, in _login
    wlogin.prompt_api_key()
  File "/om2/user/jackking/anaconda/envs/mod_tran/lib/python3.9/site-packages/wandb/sdk/wandb_login.py", line 228, in prompt_api_key
    raise UsageError("api_key not configured (no-tty). call " + directive)
wandb.errors.UsageError: api_key not configured (no-tty). call wandb.login(key=[your_api_key])
WARNING:torch.distributed.elastic.multiprocessing.api:Sending process 4959 closing signal SIGTERM
WARNING:torch.distributed.elastic.multiprocessing.api:Sending process 4960 closing signal SIGTERM
ERROR:torch.distributed.elastic.multiprocessing.api:failed (exitcode: 1) local_rank: 2 (pid: 4961) of binary: /om2/user/jackking/anaconda/envs/mod_tran/bin/python
Traceback (most recent call last):
  File "/om2/user/jackking/anaconda/envs/mod_tran/bin/accelerate", line 8, in <module>
    sys.exit(main())
  File "/om2/user/jackking/anaconda/envs/mod_tran/lib/python3.9/site-packages/accelerate/commands/accelerate_cli.py", line 45, in main
    args.func(args)
  File "/om2/user/jackking/anaconda/envs/mod_tran/lib/python3.9/site-packages/accelerate/commands/launch.py", line 908, in launch_command
    deepspeed_launcher(args)
  File "/om2/user/jackking/anaconda/envs/mod_tran/lib/python3.9/site-packages/accelerate/commands/launch.py", line 647, in deepspeed_launcher
    distrib_run.run(args)
  File "/om2/user/jackking/anaconda/envs/mod_tran/lib/python3.9/site-packages/torch/distributed/run.py", line 785, in run
    elastic_launch(
  File "/om2/user/jackking/anaconda/envs/mod_tran/lib/python3.9/site-packages/torch/distributed/launcher/api.py", line 134, in __call__
    return launch_agent(self._config, self._entrypoint, list(args))
  File "/om2/user/jackking/anaconda/envs/mod_tran/lib/python3.9/site-packages/torch/distributed/launcher/api.py", line 250, in launch_agent
    raise ChildFailedError(
torch.distributed.elastic.multiprocessing.errors.ChildFailedError: 
============================================================
/om2/user/jackking/modular_transformers//modular_transformers/train/accelerate_train_gpt2.py FAILED
------------------------------------------------------------
Failures:
  <NO_OTHER_FAILURES>
------------------------------------------------------------
Root Cause (first observed failure):
[0]:
  time      : 2023-04-25_00:17:02
  host      : node094.ib.cluster
  rank      : 2 (local_rank: 2)
  exitcode  : 1 (pid: 4961)
  error_file: <N/A>
  traceback : To enable traceback see: https://pytorch.org/docs/stable/elastic/errors.html
============================================================
